Workbook

Sheet Test cases
A1: TC ID | B1: Story | C1: AC | D1: Type | E1: Title | F1: Preconditions | G1: Test data | H1: Steps | I1: Expected result | J1: Priority | K1: Rules | L1: Status
A2: TC-001 | B2: RC-01 | C2: RC-01.1 | D2: Positive | E2: Upload the sample file with the file picker | F2: Report card page open on a laptop; device date 28-09-2026; no report showing | G2: bakery sept FINAL 2.csv | H2: 1) Click "Choose CSV file" and pick bakery sept FINAL 2.csv. 2) Look at the whole report card. | I2: Header shows "September 2026", "bakery sept FINAL 2.csv" and "14 posts graded · 9 rows not graded"; Overall: 10.5%, A+; Instagram: 11.1%, A+; YouTube: 2.6%, C; top 3: row 18 (55.9%, A+), row 6 (12.2%, A+), row 10 (9.7%, A); bottom 3, worst first: row 17 (0.8%, D), row 11 (1.4%, C), row 23 (2.2%, C); "Rows to fix" shows exactly these 7 lines, in this order: Row 8: Views must be a full number, like 12400 or 12,400. "12.4K" is not accepted. | Row 9: "Facebook" is not supported. Use Instagram or YouTube. | Row 15: 14-09-2062 is in the future. | Row 19: Likes is empty. Enter 0 if there were none. | Row 20: The year must have 4 digits, for example 21-09-2026. | Row 22: Views must be a full number, like 12400 or 12,400. "1.2L" is not accepted. | Row 24: 31-09-2026 is not a real date.; "Skipped": Row 13: Same as row 12. Counted once.; "Too new to grade": Row 25: 0 views. Not graded yet. | J2: Must | K2: BR-10, BR-18 | L2: Not run
A3: TC-002 | B3: RC-01 | C3: RC-01.1 | D3: Negative | E3: The file never leaves the browser and nothing is stored | F3: Report card page open on a laptop; device date 28-09-2026; no report showing; browser developer tools open on the Network and Application tabs | G3: bakery sept FINAL 2.csv | H3: 1) Clear the Network log. 2) Click "Choose CSV file" and pick bakery sept FINAL 2.csv. 3) Search all network request payloads for "kaju katli". 4) In the Application tab, open Local storage, Session storage, IndexedDB and Cookies for the page. | I3: No network request contains "kaju katli" or any other text from the file; Local storage, Session storage, IndexedDB and Cookies hold no file contents and no report figures | J3: Must | K3: BR-18 | L3: Not run
A4: TC-003 | B4: RC-01 | C4: RC-01.2 | D4: Positive | E4: Upload the sample file by drag and drop | F4: Report card page open on a laptop; device date 28-09-2026; no report showing | G4: bakery sept FINAL 2.csv | H4: 1) Drag bakery sept FINAL 2.csv from the computer onto the upload area. 2) Look at the whole report card. | I4: Same report card as TC-001: Header shows "September 2026", "bakery sept FINAL 2.csv" and "14 posts graded · 9 rows not graded"; Overall: 10.5%, A+; Instagram: 11.1%, A+; YouTube: 2.6%, C; top 3: row 18 (55.9%, A+), row 6 (12.2%, A+), row 10 (9.7%, A); bottom 3, worst first: row 17 (0.8%, D), row 11 (1.4%, C), row 23 (2.2%, C); "Rows to fix" shows exactly these 7 lines, in this order: Row 8: Views must be a full number, like 12400 or 12,400. "12.4K" is not accepted. | Row 9: "Facebook" is not supported. Use Instagram or YouTube. | Row 15: 14-09-2062 is in the future. | Row 19: Likes is empty. Enter 0 if there were none. | Row 20: The year must have 4 digits, for example 21-09-2026. | Row 22: Views must be a full number, like 12400 or 12,400. "1.2L" is not accepted. | Row 24: 31-09-2026 is not a real date.; "Skipped": Row 13: Same as row 12. Counted once.; "Too new to grade": Row 25: 0 views. Not graded yet. | J4: Must | K4: BR-10, BR-18 | L4: Not run
A5: TC-004 | B5: RC-01 | C5: RC-01.3 | D5: Positive | E5: Upload the sample file on a phone | F5: Report card page open on a phone 360 px wide; device date 28-09-2026; no report showing | G5: bakery sept FINAL 2.csv | H5: 1) Tap "Choose CSV file" and pick bakery sept FINAL 2.csv. 2) Scroll through the whole report card. | I5: Same report card as TC-001: Header shows "September 2026", "bakery sept FINAL 2.csv" and "14 posts graded · 9 rows not graded"; Overall: 10.5%, A+; Instagram: 11.1%, A+; YouTube: 2.6%, C; top 3: row 18 (55.9%, A+), row 6 (12.2%, A+), row 10 (9.7%, A); bottom 3, worst first: row 17 (0.8%, D), row 11 (1.4%, C), row 23 (2.2%, C); "Rows to fix" shows exactly these 7 lines, in this order: Row 8: Views must be a full number, like 12400 or 12,400. "12.4K" is not accepted. | Row 9: "Facebook" is not supported. Use Instagram or YouTube. | Row 15: 14-09-2062 is in the future. | Row 19: Likes is empty. Enter 0 if there were none. | Row 20: The year must have 4 digits, for example 21-09-2026. | Row 22: Views must be a full number, like 12400 or 12,400. "1.2L" is not accepted. | Row 24: 31-09-2026 is not a real date.; "Skipped": Row 13: Same as row 12. Counted once.; "Too new to grade": Row 25: 0 views. Not graded yet.; nothing on the page scrolls sideways | J5: Must | K5: BR-10, BR-18 | L5: Not run
A6: TC-005 | B6: RC-01 | C6: RC-01.4 | D6: Positive | E6: A second upload fully replaces the first report | F6: Report card page open on a laptop; device date 28-09-2026; report for bakery sept FINAL 2.csv showing | G6: ep1-replace.csv | H6: 1) Click "Choose CSV file" and pick ep1-replace.csv. 2) Look at the whole report card. | I6: Header shows "September 2026" and "ep1-replace.csv"; Overall: 5.0%, B; Instagram: 5.0%, B, 1,000 views, 50 interactions, 1 post; YouTube: "No graded YouTube posts this month" and no grade; "bakery sept FINAL 2.csv", 10.5%, the sample's top 3 and bottom 3, and the "Rows to fix", "Skipped" and "Too new to grade" lines from the sample file do not appear anywhere | J6: Must | K6: BR-10, BR-18 | L6: Not run
A7: TC-006 | B7: RC-02 | C7: RC-02.1 | D7: Negative | E7: Excel file is rejected | F7: Report card page open on a laptop; device date 28-09-2026; no report showing | G7: ep1-sample.xlsx | H7: 1) Drag ep1-sample.xlsx from the computer onto the upload area. 2) Look at the page. | I7: "Reach can read CSV files only. In Excel, choose File > Save As, pick "CSV UTF-8", then upload that file." is shown; no report card is shown | J7: Must | K7: BR-14 | L7: Not run
A8: TC-007 | B8: RC-02 | C8: RC-02.1 | D8: Negative | E8: File with CSV contents but a .txt name is rejected | F8: Report card page open on a laptop; device date 28-09-2026; no report showing | G8: ep1-sample.txt | H8: 1) Drag ep1-sample.txt from the computer onto the upload area. 2) Look at the page. | I8: "Reach can read CSV files only. In Excel, choose File > Save As, pick "CSV UTF-8", then upload that file." is shown; no report card is shown | J8: Must | K8: BR-14, Field spec (File type) | L8: Not run
A9: TC-008 | B9: RC-02 | C9: RC-02.2 | D9: Negative | E9: CSV with no Saves column is rejected | F9: Report card page open on a laptop; device date 28-09-2026; no report showing | G9: ep1-no-saves.csv | H9: 1) Click "Choose CSV file" and pick ep1-no-saves.csv. 2) Look at the page. | I9: "This file is missing the column(s): Saves. The first row must have Date, Platform, Caption, Views, Likes, Comments, Shares and Saves." is shown; no report card is shown | J9: Must | K9: BR-14, Field spec (Column headers) | L9: Not run
A10: TC-009 | B10: RC-02 | C10: RC-02.2 | D10: Negative | E10: CSV with no Date column is rejected | F10: Report card page open on a laptop; device date 28-09-2026; no report showing | G10: ep1-no-date.csv | H10: 1) Click "Choose CSV file" and pick ep1-no-date.csv. 2) Look at the page. | I10: "This file is missing the column(s): Date. The first row must have Date, Platform, Caption, Views, Likes, Comments, Shares and Saves." is shown; no report card is shown | J10: Must | K10: BR-14, Field spec (Column headers) | L10: Not run
A11: TC-010 | B11: RC-02 | C11: RC-02.3 | D11: Positive | E11: Header " Views" with a leading space is read | F11: Report card page open on a laptop; device date 28-09-2026; no report showing | G11: bakery sept FINAL 2.csv | H11: 1) Click "Choose CSV file" and pick bakery sept FINAL 2.csv. 2) Look at the page and the Instagram section. | I11: No "missing the column(s)" message; Instagram: 2,10,100 views | J11: Must | K11: BR-14, Field spec (Column headers) | L11: Not run
A12: TC-011 | B12: RC-02 | C12: RC-02.3 | D12: Edge | E12: Headers in mixed capitals are read | F12: Report card page open on a laptop; device date 28-09-2026; no report showing | G12: ep1-header-caps.csv | H12: 1) Click "Choose CSV file" and pick ep1-header-caps.csv. 2) Look at the page and the Overall section. | I12: No "missing the column(s)" message; Overall: 5.0%, B | J12: Must | K12: BR-14, Field spec (Column headers) | L12: Not run
... A139: TC-138 | B139: RC-26 | C139: RC-26.1 | D139: Negative | E139: No earlier report is kept in this release | F139: Report card page open on a laptop; device date 28-09-2026; report for bakery sept FINAL 2.csv showing | G139: bakery sept FINAL 2.csv | H139: 1) Refresh the page. 2) Look over the whole page for any earlier report or report history. | I139: No report is shown and no earlier report can be opened from anywhere on the page | J139: Won't | K139: BR-18 | L139: Not run

Sheet Coverage
A1: AC ID | B1: Story | C1: Story title | D1: Priority | E1: Then (from requirements) | F1: TC IDs | G1: No. of TCs | H1: Coverage | I1: Open questions
A2: RC-01.1 | B2: RC-01 | C2: Upload a CSV | D2: Must | E2: Then the report card for September 2026 is shown | F2: TC-001, TC-002 | G2: =COUNTIF('Test cases'!$C$2:$C$139,A2) -> 2 | H2: =IF(G2=0,"NO TEST CASE","Covered") -> Covered | I2: Q-02, Q-07
A3: RC-01.2 | B3: RC-01 | C3: Upload a CSV | D3: Must | E3: Then the same report card as in RC-01.1 is shown | F3: TC-003 | G3: =COUNTIF('Test cases'!$C$2:$C$139,A3) -> 1 | H3: =IF(G3=0,"NO TEST CASE","Covered") -> Covered | I3: Q-02, Q-07
A4: RC-01.3 | B4: RC-01 | C4: Upload a CSV | D4: Must | E4: Then the same report card as in RC-01.1 is shown | F4: TC-004 | G4: =COUNTIF('Test cases'!$C$2:$C$139,A4) -> 1 | H4: =IF(G4=0,"NO TEST CASE","Covered") -> Covered | I4: Q-02, Q-07, Q-09
A5: RC-01.4 | B5: RC-01 | C5: Upload a CSV | D5: Must | E5: Then the first report is fully replaced by the new one | F5: TC-005 | G5: =COUNTIF('Test cases'!$C$2:$C$139,A5) -> 1 | H5: =IF(G5=0,"NO TEST CASE","Covered") -> Covered | I5: Q-31
A6: RC-02.1 | B6: RC-02 | C6: Reject a file Reach can't use | D6: Must | E6: Then "Reach can read CSV files only. In Excel, choose File > Save As, pick "CSV UTF-8", then upload that file." is shown and no report is shown | F6: TC-006, TC-007 | G6: =COUNTIF('Test cases'!$C$2:$C$139,A6) -> 2 | H6: =IF(G6=0,"NO TEST CASE","Covered") -> Covered | I6: Q-39
A7: RC-02.2 | B7: RC-02 | C7: Reject a file Reach can't use | D7: Must | E7: Then "This file is missing the column(s): Saves. The first row must have Date, Platform, Caption, Views, Likes, Comments, Shares and Saves." is shown and no report is shown | F7: TC-008, TC-009 | G7: =COUNTIF('Test cases'!$C$2:$C$139,A7) -> 2 | H7: =IF(G7=0,"NO TEST CASE","Covered") -> Covered
A8: RC-02.3 | B8: RC-02 | C8: Reject a file Reach can't use | D8: Must | E8: Then the Views column is read with no error | F8: TC-010, TC-011 | G8: =COUNTIF('Test cases'!$C$2:$C$139,A8) -> 2 | H8: =IF(G8=0,"NO TEST CASE","Covered") -> Covered | I8: Q-31
A9: RC-02.4 | B9: RC-02 | C9: Reject a file Reach can't use | D9: Must | E9: Then the report matches the sample file's report | F9: TC-012 | G9: =COUNTIF('Test cases'!$C$2:$C$139,A9) -> 1 | H9: =IF(G9=0,"NO TEST CASE","Covered") -> Covered | I9: Q-02
A10: RC-02.5 | B10: RC-02 | C10: Reject a file Reach can't use | D10: Must | E10: Then the Link column is ignored and no message is shown | F10: TC-013 | G10: =COUNTIF('Test cases'!$C$2:$C$139,A10) -> 1 | H10: =IF(G10=0,"NO TEST CASE","Covered") -> Covered | I10: Q-31
A11: RC-02.6 | B11: RC-02 | C11: Reject a file Reach can't use | D11: Must | E11: Then "This file has no posts in it." is shown | F11: TC-014, TC-015 | G11: =COUNTIF('Test cases'!$C$2:$C$139,A11) -> 2 | H11: =IF(G11=0,"NO TEST CASE","Covered") -> Covered
A12: RC-02.7 | B12: RC-02 | C12: Reject a file Reach can't use | D12: Must | E12: Then "This file is over 5 MB. Upload one client's month at a time." is shown and no report is shown | F12: TC-016, TC-017 | G12: =COUNTIF('Test cases'!$C$2:$C$139,A12) -> 2 | H12: =IF(G12=0,"NO TEST CASE","Covered") -> Covered | I12: Q-14
A13: RC-02.8 | B13: RC-02 | C13: Reject a file Reach can't use | D13: Must | E13: Then "This file has more than 10,000 rows. Upload one client's month at a time." is shown and no report is shown | F13: TC-018 | G13: =COUNTIF('Test cases'!$C$2:$C$139,A13) -> 1 | H13: =IF(G13=0,"NO TEST CASE","Covered") -> Covered
A14: RC-02.9 | B14: RC-02 | C14: Reject a file Reach can't use | D14: Must | E14: Then the file is accepted and the report is shown | F14: TC-019 | G14: =COUNTIF('Test cases'!$C$2:$C$139,A14) -> 1 | H14: =IF(G14=0,"NO TEST CASE","Covered") -> Covered
A15: RC-03.1 | B15: RC-03 | C15: Upload an Excel file | D15: Won't | E15: Then Reach behaves as in RC-02.1 | F15: TC-020 | G15: =COUNTIF('Test cases'!$C$2:$C$139,A15) -> 1 | H15: =IF(G15=0,"NO TEST CASE","Covered") -> Covered | I15: Q-39
A16: RC-04.1 | B16: RC-04 | C16: See which rows weren't graded and why | D16: Must | E16: Then grades are shown for the 14 graded posts even though other rows have problems | F16: TC-021, TC-022 | G16: =COUNTIF('Test cases'!$C$2:$C$139,A16) -> 2 | H16: =IF(G16=0,"NO TEST CASE","Covered") -> Covered | I16: Q-02
A17: RC-04.2 | B17: RC-04 | C17: See which rows weren't graded and why | D17: Must | E17: Then the "Rows to fix" list shows exactly these 7 lines, in this order: Row 8: Views must be a full number, like 12400 or 12,400. "12.4K" is not accepted. Row 9: "Facebook" is not supported. Use Instagram or YouTube. Row 15: 14-09-2062 is in the future. Row 19: Likes is empty. Enter 0 if there were none. Row 20: The year must have 4 digits, for example 21-09-2026. Row 22: Views must be a full number, like 12400 or 12,400. "1.2L" is not accepted. Row 24: 31-09-2026 is not a real date. | F17: TC-023 | G17: =COUNTIF('Test cases'!$C$2:$C$139,A17) -> 1 | H17: =IF(G17=0,"NO TEST CASE","Covered") -> Covered
A18: RC-04.3 | B18: RC-04 | C18: See which rows weren't graded and why | D18: Must | E18: Then two lines are shown for that row, one per problem, both with the same row number | F18: TC-024, TC-025 | G18: =COUNTIF('Test cases'!$C$2:$C$139,A18) -> 2 | H18: =IF(G18=0,"NO TEST CASE","Covered") -> Covered | I18: Q-20, Q-29
A19: RC-04.4 | B19: RC-04 | C19: See which rows weren't graded and why | D19: Must | E19: Then no grades are shown and "No rows could be graded. Fix the rows listed below and upload again." is shown above the list | F19: TC-026 | G19: =COUNTIF('Test cases'!$C$2:$C$139,A19) -> 1 | H19: =IF(G19=0,"NO TEST CASE","Covered") -> Covered | I19: Q-25
A20: RC-04.5 | B20: RC-04 | C20: See which rows weren't graded and why | D20: Must | E20: Then no "Rows to fix" section is shown | F20: TC-027 | G20: =COUNTIF('Test cases'!$C$2:$C$139,A20) -> 1 | H20: =IF(G20=0,"NO TEST CASE","Covered") -> Covered | I20: Q-30
A21: RC-04.6 | B21: RC-04 | C21: See which rows weren't graded and why | D21: Must | E21: Then the "Rows to fix", "Skipped" and "Too new to grade" lists appear below the bottom 3 posts | F21: TC-028 | G21: =COUNTIF('Test cases'!$C$2:$C$139,A21) -> 1 | H21: =IF(G21=0,"NO TEST CASE","Covered") -> Covered | I21: Q-21, Q-30
A22: RC-05.1 | B22: RC-05 | C22: Read the date formats Excel produces | D22: Must | E22: Then the post is dated 03-09-2026 (3 September, not 9 March) | F22: TC-029 | G22: =COUNTIF('Test cases'!$C$2:$C$139,A22) -> 1 | H22: =IF(G22=0,"NO TEST CASE","Covered") -> Covered | I22: Q-12, Q-41
A23: RC-05.2 | B23: RC-05 | C23: Read the date formats Excel produces | D23: Must | E23: Then the post is dated 06-09-2026 | F23: TC-030 | G23: =COUNTIF('Test cases'!$C$2:$C$139,A23) -> 1 | H23: =IF(G23=0,"NO TEST CASE","Covered") -> Covered | I23: Q-12, Q-41
A24: RC-05.3 | B24: RC-05 | C24: Read the date formats Excel produces | D24: Must | E24: Then the row is listed as "Row 20: The year must have 4 digits, for example 21-09-2026." and is not graded | F24: TC-031, TC-032 | G24: =COUNTIF('Test cases'!$C$2:$C$139,A24) -> 2 | H24: =IF(G24=0,"NO TEST CASE","Covered") -> Covered | I24: Q-02
A25: RC-05.4 | B25: RC-05 | C25: Read the date formats Excel produces | D25: Must | E25: Then the row is listed as "Row 24: 31-09-2026 is not a real date." | F25: TC-033, TC-034 | G25: =COUNTIF('Test cases'!$C$2:$C$139,A25) -> 2 | H25: =IF(G25=0,"NO TEST CASE","Covered") -> Covered
A26: RC-05.5 | B26: RC-05 | C26: Read the date formats Excel produces | D26: Must | E26: Then that row is listed as "Row {n}: 30-08-2026 is not in September 2026. Upload one month per file." | F26: TC-035, TC-036, TC-037 | G26: =COUNTIF('Test cases'!$C$2:$C$139,A26) -> 3 | H26: =IF(G26=0,"NO TEST CASE","Covered") -> Covered
A27: RC-05.6 | B27: RC-05 | C27: Read the date formats Excel produces | D27: Must | E27: Then the post is dated 03-09-2026 | F27: TC-038 | G27: =COUNTIF('Test cases'!$C$2:$C$139,A27) -> 1 | H27: =IF(G27=0,"NO TEST CASE","Covered") -> Covered | I27: Q-32
A28: RC-05.7 | B28: RC-05 | C28: Read the date formats Excel produces | D28: Must | E28: Then the post is dated 03-09-2026 | F28: TC-039 | G28: =COUNTIF('Test cases'!$C$2:$C$139,A28) -> 1 | H28: =IF(G28=0,"NO TEST CASE","Covered") -> Covered | I28: Q-32
A29: RC-05.8 | B29: RC-05 | C29: Read the date formats Excel produces | D29: Must | E29: Then the row is listed as "Row {n}: "03-09/2026" is not a date Reach can read. Write it as DD-MM-YYYY, for example 21-09-2026." | F29: TC-040 | G29: =COUNTIF('Test cases'!$C$2:$C$139,A29) -> 1 | H29: =IF(G29=0,"NO TEST CASE","Covered") -> Covered
A30: RC-06.1 | B30: RC-06 | C30: Accept short platform names | D30: Must | E30: Then both are counted as Instagram | F30: TC-041 | G30: =COUNTIF('Test cases'!$C$2:$C$139,A30) -> 1 | H30: =IF(G30=0,"NO TEST CASE","Covered") -> Covered
A31: RC-06.2 | B31: RC-06 | C31: Accept short platform names | D31: Must | E31: Then it is counted as YouTube | F31: TC-042 | G31: =COUNTIF('Test cases'!$C$2:$C$139,A31) -> 1 | H31: =IF(G31=0,"NO TEST CASE","Covered") -> Covered
A32: RC-06.3 | B32: RC-06 | C32: Accept short platform names | D32: Must | E32: Then it is counted as Instagram | F32: TC-043, TC-044, TC-045 | G32: =COUNTIF('Test cases'!$C$2:$C$139,A32) -> 3 | H32: =IF(G32=0,"NO TEST CASE","Covered") -> Covered | I32: Q-31
A33: RC-07.1 | B33: RC-07 | C33: Read numbers with commas, NA and "-" | D33: Must | E33: Then Views is read as 1,25,000 | F33: TC-046 | G33: =COUNTIF('Test cases'!$C$2:$C$139,A33) -> 1 | H33: =IF(G33=0,"NO TEST CASE","Covered") -> Covered | I33: Q-03, Q-10
A34: RC-07.2 | B34: RC-07 | C34: Read numbers with commas, NA and "-" | D34: Must | E34: Then Views is read as 12,400 | F34: TC-047, TC-048, TC-049 | G34: =COUNTIF('Test cases'!$C$2:$C$139,A34) -> 3 | H34: =IF(G34=0,"NO TEST CASE","Covered") -> Covered | I34: Q-31
A35: RC-07.3 | B35: RC-07 | C35: Read numbers with commas, NA and "-" | D35: Must | E35: Then Saves counts as 0 and no message is shown | F35: TC-050 | G35: =COUNTIF('Test cases'!$C$2:$C$139,A35) -> 1 | H35: =IF(G35=0,"NO TEST CASE","Covered") -> Covered
A36: RC-07.4 | B36: RC-07 | C36: Read numbers with commas, NA and "-" | D36: Must | E36: Then Saves counts as 0 and no message is shown | F36: TC-051 | G36: =COUNTIF('Test cases'!$C$2:$C$139,A36) -> 1 | H36: =IF(G36=0,"NO TEST CASE","Covered") -> Covered | I36: Q-31
A37: RC-07.5 | B37: RC-07 | C37: Read numbers with commas, NA and "-" | D37: Must | E37: Then "Row {n}: Likes must be a full number, like 12400 or 12,400. "-5" is not accepted." is shown | F37: TC-052, TC-053, TC-054, TC-055, TC-056, TC-057 | G37: =COUNTIF('Test cases'!$C$2:$C$139,A37) -> 6 | H37: =IF(G37=0,"NO TEST CASE","Covered") -> Covered
A38: RC-07.6 | B38: RC-07 | C38: Read numbers with commas, NA and "-" | D38: Must | E38: Then "Row {n}: Views must be a full number, like 12400 or 12,400. "12.5" is not accepted." is shown | F38: TC-058, TC-059 | G38: =COUNTIF('Test cases'!$C$2:$C$139,A38) -> 2 | H38: =IF(G38=0,"NO TEST CASE","Covered") -> Covered
A39: RC-07.7 | B39: RC-07 | C39: Read numbers with commas, NA and "-" | D39: Must | E39: Then Shares counts as 0 and the post is graded at 1.4% (25 ÷ 1,840), grade C | F39: TC-060 | G39: =COUNTIF('Test cases'!$C$2:$C$139,A39) -> 1 | H39: =IF(G39=0,"NO TEST CASE","Covered") -> Covered
A40: RC-07.8 | B40: RC-07 | C40: Read numbers with commas, NA and "-" | D40: Must | E40: Then Shares counts as 0 and no message is shown | F40: TC-061 | G40: =COUNTIF('Test cases'!$C$2:$C$139,A40) -> 1 | H40: =IF(G40=0,"NO TEST CASE","Covered") -> Covered | I40: Q-31
...

Sheet Test data
A1: File name | B1: Exactly what's in it | C1: How to make it | D1: Used by (TC IDs)
A2: bakery sept FINAL 2.csv | B2: Date,Platform,Caption, Views,Likes,Comments,Shares,Saves,Notes 01-09-2026,Instagram,"Fresh rusk, straight out of the oven 🍞","12,400",610,38,45,52, 02-09-2026,YouTube,How we make our eggless chocolate cake,3150,96,11,4,NA, 03/09/2026,insta,Weekend special: kaju katli box,18900,1240,96,310,185,Boosted ₹500 ,,,,,,,, 05-09-2026,IG,"Teachers' Day cupcakes, free for every teacher who walks in 🧁","1,25,000","10,400",720,"2,450","1,630", 2026-09-06,YouTube,Bakery tour in 60 seconds,5200,140,9,6,NA, 07-09-2026,Instagram,Our chef's secret: brown butter cookies,12.4K,530,21,60,88, 08-09-2026,Facebook,"Same cookie reel, posted on FB",2300,45,2,3,,Test 09-09-2026,Instagram,नई ब्रांच खुल गई! आप सबका शुक्रिया 🎉,"21,700","1,560",212,240,96,Collab with a food blogger 10-09-2026,YT,Customer reviews our new pav,1840,22,3,-,NA, 11-09-2026,Instagram,Rainy day + chai + our rusk ☔,9600,310,14,33,41, 11-09-2026,Instagram,Rainy day + chai + our rusk ☔,9600,310,14,33,41, 13-09-2026,YouTube,Behind the scenes: 4 AM at the bakery,2480,58,7,2,NA, 14-09-2062,Instagram,Monsoon combo: chai + 2 rusk packs,6100,190,9,14,22, 16-09-2026,Instagram,Staff picks: our top 5 breads,6900,150,6,11,17, 17-09-2026,YouTube,Full recipe: bakery-style bun maska,1120,8,1,0,NA, 18-09-2026,Instagram,Giveaway! Tag a friend who loves cake 🎂,4300,520,1840,30,12,Giveaway 20-09-2026,Instagram,Kids' birthday cake ideas,8200,,15,20,64, 21/9/26,YouTube,Q&A: eggless baking tips,980,31,6,1,NA, 22-09-2026,Instagram,Brunch at the bakery: new menu,"11,300",420,19,28,35, 24-09-2026,Instagram,Sold out in 2 hours: cinnamon rolls,1.2L,6900,380,1150,980,Our best one!! 25-09-2026,YouTube,Why our bread has no preservatives,2750,49,8,3,NA, 31-09-2026,Instagram,Weekend brunch menu,7800,240,12,18,30, 26-09-2026,Instagram,Sneak peek: festive cookie hampers,0,0,0,0,0,Posted today ,,,,,,,, ,,,,,,,, | C2: Supplied by the BA with the v1 requirements. Use it exactly as supplied; don't open and re-save it in Excel. It starts with a UTF-8 byte order mark and has 27 lines (rows 5, 26 and 27 are blank). | D2: TC-001, TC-002, TC-003, TC-004, TC-010, TC-021, TC-023, TC-028, TC-029, TC-030, TC-031, TC-033, TC-041, TC-042, TC-046, TC-047, TC-050, TC-060, TC-062, TC-063, TC-065, TC-069, TC-070, TC-071, TC-072, TC-077, TC-079, TC-080, TC-083, TC-086, TC-087, TC-105, TC-106, TC-108, TC-112, TC-113, TC-114, TC-115, TC-116, TC-117, TC-118, TC-122, TC-123, TC-125, TC-126, TC-129, TC-130, TC-131, TC-132, TC-133, TC-134, TC-135, TC-136, TC-137, TC-138
A3: ep1-replace.csv | B3: Date,Platform,Caption,Views,Likes,Comments,Shares,Saves 10-09-2026,Instagram,Replacement post,1000,50,0,0,0 | C3: Save as CSV UTF-8. Line 1 is the header; each following line is one row (row 2 onwards). | D3: TC-005, TC-134
A4: ep1-sample.xlsx | B4: The sample file's rows and columns, as an Excel workbook. | C4: Open bakery sept FINAL 2.csv in Excel, choose File > Save As, pick "Excel Workbook (.xlsx)", name it ep1-sample.xlsx. | D4: TC-006, TC-020
A5: ep1-sample.txt | B5: Byte-for-byte copy of bakery sept FINAL 2.csv. | C5: Copy bakery sept FINAL 2.csv and rename the copy to ep1-sample.txt. | D5: TC-007
A6: ep1-no-saves.csv | B6: Date,Platform,Caption,Views,Likes,Comments,Shares 10-09-2026,Instagram,Valid post,1000,50,0,0 | C6: Save as CSV UTF-8. Line 1 is the header; each following line is one row (row 2 onwards). | D6: TC-008
A7: ep1-no-date.csv | B7: Platform,Caption,Views,Likes,Comments,Shares,Saves Instagram,Valid post,1000,50,0,0,0 | C7: Save as CSV UTF-8. Line 1 is the header; each following line is one row (row 2 onwards). | D7: TC-009
A8: ep1-header-caps.csv | B8: DATE,platform,CAPTION,views,LIKES,comments,SHARES,saves 10-09-2026,Instagram,Valid post,1000,50,0,0,0 | C8: Save as CSV UTF-8. Line 1 is the header; each following line is one row (row 2 onwards). | D8: TC-011
A9: ep1-sample-reordered.csv | B9: Notes,Saves,Shares,Comments,Likes, Views,Caption,Platform,Date ,52,45,38,610,"12,400","Fresh rusk, straight out of the oven 🍞",Instagram,01-09-2026 ,NA,4,11,96,3150,How we make our eggless chocolate cake,YouTube,02-09-2026 Boosted ₹500,185,310,96,1240,18900,Weekend special: kaju katli box,insta,03/09/2026 ,,,,,,,, ,"1,630","2,450",720,"10,400","1,25,000","Teachers' Day cupcakes, free for every teacher who walks in 🧁",IG,05-09-2026 ,NA,6,9,140,5200,Bakery tour in 60 seconds,YouTube,2026-09-06 ,88,60,21,530,12.4K,Our chef's secret: brown butter cookies,Instagram,07-09-2026 Test,,3,2,45,2300,"Same cookie reel, posted on FB",Facebook,08-09-2026 Collab with a food blogger,96,240,212,"1,560","21,700",नई ब्रांच खुल गई! आप सबका शुक्रिया 🎉,Instagram,09-09-2026 ,NA,-,3,22,1840,Customer reviews our new pav,YT,10-09-2026 ,41,33,14,310,9600,Rainy day + chai + our rusk ☔,Instagram,11-09-2026 ,41,33,14,310,9600,Rainy day + chai + our rusk ☔,Instagram,11-09-2026 ,NA,2,7,58,2480,Behind the scenes: 4 AM at the bakery,YouTube,13-09-2026 ,22,14,9,190,6100,Monsoon combo: chai + 2 rusk packs,Instagram,14-09-2062 ,17,11,6,150,6900,Staff picks: our top 5 breads,Instagram,16-09-2026 ,NA,0,1,8,1120,Full recipe: bakery-style bun maska,YouTube,17-09-2026 Giveaway,12,30,1840,520,4300,Giveaway! Tag a friend who loves cake 🎂,Instagram,18-09-2026 ,64,20,15,,8200,Kids' birthday cake ideas,Instagram,20-09-2026 ,NA,1,6,31,980,Q&A: eggless baking tips,YouTube,21/9/26 ,35,28,19,420,"11,300",Brunch at the bakery: new menu,Instagram,22-09-2026 Our best one!!,980,1150,380,6900,1.2L,Sold out in 2 hours: cinnamon rolls,Instagram,24-09-2026 ,NA,3,8,49,2750,Why our bread has no preservatives,YouTube,25-09-2026 ,30,18,12,240,7800,Weekend brunch menu,Instagram,31-09-2026 Posted today,0,0,0,0,0,Sneak peek: festive cookie hampers,Instagram,26-09-2026 ,,,,,,,, ,,,,,,,, | C9: Save as CSV UTF-8. Line 1 is the header; each following line is one row (row 2 onwards). Same rows as the sample file with the columns in the order Notes, Saves, Shares, Comments, Likes, Views, Caption, Platform, Date. Blank rows 5, 26 and 27 are kept. | D9: TC-012
A10: ep1-extra-link.csv | B10: Date,Platform,Caption,Views,Likes,Comments,Shares,Saves,Link 10-09-2026,Instagram,Valid post,1000,50,0,0,0,post-link-1 | C10: Save as CSV UTF-8. Line 1 is the header; each following line is one row (row 2 onwards). | D10: TC-013
A11: ep1-header-only.csv | B11: Date,Platform,Caption,Views,Likes,Comments,Shares,Saves | C11: Save as CSV UTF-8. Line 1 is the header; each following line is one row (row 2 onwards). The file has only this one line. | D11: TC-014
A12: ep1-header-blank-rows.csv | B12: Date,Platform,Caption,Views,Likes,Comments,Shares,Saves ,,,,,,, ,,,,,,, ,,,,,,, | C12: Save as CSV UTF-8. Line 1 is the header; each following line is one row (row 2 onwards). | D12: TC-015
... A66: ep4-six-posts.csv | B66: Date,Platform,Caption,Views,Likes,Comments,Shares,Saves 13-09-2026,Instagram,Post D,1000,30,0,0,0 10-09-2026,Instagram,Post A,1000,60,0,0,0 15-09-2026,Instagram,Post F,1000,10,0,0,0 11-09-2026,Instagram,Post B,1000,50,0,0,0 14-09-2026,Instagram,Post E,1000,20,0,0,0 12-09-2026,Instagram,Post C,1000,40,0,0,0 | C66: Save as CSV UTF-8. Line 1 is the header; each following line is one row (row 2 onwards). | D66: TC-128
